Workbook
Name SegmentaciónDeDatos_Mes1: #N/A
Name SegmentaciónDeDatos_Mes21: #N/A
Name SegmentaciónDeDatos_Mes3: #N/A
Name SegmentaciónDeDatos_Mes41: #N/A
Name SegmentaciónDeDatos_Semana1: #N/A
Name SegmentaciónDeDatos_Semana21: #N/A
Name SegmentaciónDeDatos_Semana3: #N/A
Name SegmentaciónDeDatos_Semana41: #N/A

Sheet Catalogo
A1: Descripción SKU | B1: Producto | C1: Empresa | E1: SKU | F1: Descripción SKU | G1: Producto | H1: Empresa
A2: "[79669] FLOW SWITCH 24VAC/DC,SS 1/2""NPT (SC050R)" | B2: [79669] FLOW SWITCH 24VAC/DC,SS 1/2" | C2: Supra System | E2: LD018-4 | F2: [LD018-4] ADBS (TAMBOR PLASTICO 220 KG INC) | G2: ADBS | H2: Liderza
A3: "[LD117] TRICLORO TABLETA 3"" CUÑETE 50 KG" | B3: TRICLORO TABLETA 3" | C3: Liderza | E3: LD002-2 | F3: [LD002-2] ACEITE DE PINO L (TAMBOR LAMINA 200 L INC) | G3: ACEITE DE PINO | H3: Liderza
A4: "[SS008] TRICLORO TABLETA 3"" CUÑETE 50 KG" | B4: TRICLORO TABLETA 3" | C4: Supra System | E4: LD023-4 | F4: [LD023-4] ALCOHOL TRIDECILICO 8 MOLES (TAMBOR PLASTICO 200 KG INC) | G4: ALCOHOL TRIDECILICO 8 MOLES | H4: Liderza
A5: [73250] PULSAR PRECISION | B5: [73250] PULSAR PRECISION | C5: Supra System | E5: LD001-4 | F5: ACEITE DE PINO KG | G5: ACEITE DE PINO | H5: Liderza
A6: [73350] PULSAR ACID PLUS FEEDER (pH) | B6: [73350] PULSAR ACID PLUS FEEDER (pH) | C6: Supra System | E6: LD008-3 | F6: ACIDO ACETICO GLACIAL ALIMENTICIO | G6: ACIDO ACETICO GLACIAL ALIMENTICIO | H6: Liderza
A7: [73371] PULSAR PRECISION 30 (with install kit) | B7: [73371] PULSAR PRECISION 30 (with install kit) | C7: Supra System | E7: LD012 | F7: ACIDO CITRICO WEIFANG SACO 25 KG | G7: ACIDO CITRICO WEIFANG | H7: Liderza
A8: [73379] PULSAR PRECISION 30 (mini) | B8: [73379] PULSAR PRECISION 30 (mini) | C8: Supra System | E8: LD016-1 | F8: ACIDO FOSFORICO CLARIFICADO 85% | G8: ACIDO FOSFORICO CLARIFICADO 85% | H8: Liderza
A9: [73389] HCE 30 - ORP KIT | B9: [73389] HCE 30 - ORP KIT | C9: Supra System | E9: LD016-9 | F9: ACIDO FOSFORICO CLARIFICADO 85% | G9: ACIDO FOSFORICO CLARIFICADO 85% | H9: Liderza
A10: [73433] PULSAR CONTROLLER M720 | B10: [73433] PULSAR CONTROLLER M720 | C10: Supra System | E10: LD020-3 | F10: ALCOHOL ETILICO | G10: ALCOHOL ETILICO | H10: Liderza
A11: [73434] PH SENSOR (SXPH) | B11: [73434] PH SENSOR | C11: Supra System | E11: LD028-2 | F11: AROMINA 150 | G11: AROMINA 150 | H11: Liderza
A12: [73435] ORP SENSOR (SXORP) | B12: [73435] ORP SENSOR | C12: Supra System | E12: LD030-1 | F12: BICARBONATO DE SODIO USP | G12: BICARBONATO DE SODIO USP | H12: Liderza
... A236: METANOL | B236: METANOL | C236: Liderza | E236: LD139 | F236: [LD139] HIPOCLORITO DE CALCIO TABLETA 2&5/8 CCH SKU 23220E CUNETE 22.7 KG | G236: HIPOCLORITO DE CALCIO TABLETA CCH | H236: Liderza
A237: METASILICATO DE SODIO PENTASIL SACO 25 KG | B237: METASILICATO DE SODIO PENTASIL | C237: Liderza
A238: MONOETANOLAMINA | B238: MONOETANOLAMINA | C238: Liderza
A239: MONOPROPILENGLICOL USP | B239: MONOPROPILENGLICOL USP | C239: Liderza
A240: NONIL FENOL 10 MOLES | B240: NONIL FENOL 10 MOLES | C240: Liderza
A241: PERCARBONATO DE SODIO PROVOX SACO 25 KG | B241: PERCARBONATO DE SODIO PROVOX | C241: Liderza
A242: PEROXIDO DE HIDROGENO 35% FG | B242: PEROXIDO DE HIDROGENO 35% FG | C242: Liderza
A243: PEROXIDO DE HIDROGENO 50% STD | B243: PEROXIDO DE HIDROGENO 50% STD | C243: Liderza
A244: PIGMENTO AMARILLO IOX Y 02 SACO 20 KG | B244: PIGMENTO AMARILLO | C244: Liderza
A245: PIGMENTO ROJO IOX R 02 SACO 25 KG | B245: PIGMENTO ROJO | C245: Liderza
A246: PISTON PARA AQT-275 Y AQT-290 HWBP | B246: PISTON PARA AQT-275 Y 290 | C246: Liderza
A247: POTASA CAUSTICA EN ESCAMA CHINA SACO 25 KG | B247: POTASA CAUSTICA EN ESCAMA CHINA | C247: Liderza
A248: POTASA CAUSTICA EN ESCAMA ROT SACO 25 KG | B248: POTASA CAUSTICA EN ESCAMA ROT | C248: Liderza
... A328: [LD097-3] PROTEINA VEGETAL PVH 11307 (SACO 22.68 KG) | B328: PROTEINA VEGETAL PVH 11307 | C328: Liderza

Sheet BD Ventas
A1: Asiento contable/Número | B1: Asiento contable/Nombre del partner para mostrar en la factura. | C1: Asiento contable/Fecha de factura | D1: Asiento contable/Partner/Términos de pago del cliente | E1: Asiento contable/Fecha de vencimiento | F1: Líneas de la orden de venta/Vendedor | G1: Líneas de la orden de venta/Producto | H1: Líneas de la orden de venta/Unidad de medida | I1: Líneas de la orden de venta/Cantidad facturada | J1: Líneas de la orden de venta/Costo | K1: Líneas de la orden de venta/Precio unitario | L1: Líneas de la orden de venta/Margen | M1: Líneas de la orden de venta/Margen (%) | N1: Líneas de la orden de venta/Divisa | O1: Crédito | P1: Mes | Q1: Semana | R1: Producto 2 | S1: Ut Bruta MN | T1: Costo Venta MN | U1: TC
A2: HMO/2026/00454 | B2: "PUBLICO EN GENERAL" | C2: 46199 | D2: Pago inmediato | E2: 46199 | F2: ILSE GARCÍA | G2: [LD052-2] ESTIREN ACRILICA (TAMBOR LAMINA 180 KG INC) | H2: KG | I2: 1800 | J2: 31.879394 | K2: 39 | L2: 12817.091 | M2: 0.18257964 | N2: MXN | O2: 70200 | P2: =MONTH(C2) -> 6 | Q2: =WEEKNUM(C2) -> 26 | R2: =VLOOKUP(G2,Catalogo!A:B,2,0) -> ESTIREN ACRILICA | S2: =(K2-J2)*I2*U2 -> 12817.091 | T2: =O2-S2 -> 57382.909 | U2: =IF(N2="USD",(O2/I2/K2),1) -> 1
A3: HMO/2026/00453 | B3: "PUBLICO EN GENERAL" | C3: 46199 | D3: Pago inmediato | E3: 46199 | F3: ILSE GARCÍA | G3: [LD052-2] ESTIREN ACRILICA (TAMBOR LAMINA 180 KG INC) | H3: KG | I3: 1800 | J3: 31.879394 | K3: 39 | L3: 12817.091 | M3: 0.18257964 | N3: MXN | O3: 70200 | P3: =MONTH(C3) -> 6 | Q3: =WEEKNUM(C3) -> 26 | R3: =VLOOKUP(G3,Catalogo!A:B,2,0) -> ESTIREN ACRILICA | S3: =(K3-J3)*I3*U3 -> 12817.091 | T3: =O3-S3 -> 57382.909 | U3: =IF(N3="USD",(O3/I3/K3),1) -> 1
A4: HMO/2026/00452 | B4: "PUBLICO EN GENERAL" | C4: 46199 | D4: Pago inmediato | E4: 46199 | F4: ILSE GARCÍA | G4: [LD052-2] ESTIREN ACRILICA (TAMBOR LAMINA 180 KG INC) | H4: KG | I4: 900 | J4: 31.879389 | K4: 39 | L4: 6408.5499 | M4: 0.18257977 | N4: MXN | O4: 35100 | P4: =MONTH(C4) -> 6 | Q4: =WEEKNUM(C4) -> 26 | R4: =VLOOKUP(G4,Catalogo!A:B,2,0) -> ESTIREN ACRILICA | S4: =(K4-J4)*I4*U4 -> 6408.5499 | T4: =O4-S4 -> 28691.45 | U4: =IF(N4="USD",(O4/I4/K4),1) -> 1
A5: HMO/2026/00451 | B5: "PUBLICO EN GENERAL" | C5: 46199 | D5: Pago inmediato | E5: 46199 | F5: ILSE GARCÍA | G5: [LD022] ALCOHOL POLIVINILICO PVOH 08850 SACO 20 KG | H5: KG | I5: 1000 | J5: 47.37745 | K5: 58 | L5: 10622.55 | M5: 0.18314741 | N5: MXN | O5: 58000 | P5: =MONTH(C5) -> 6 | Q5: =WEEKNUM(C5) -> 26 | R5: =VLOOKUP(G5,Catalogo!A:B,2,0) -> ALCOHOL POLIVINILICO PVOH 08850 | S5: =(K5-J5)*I5*U5 -> 10622.55 | T5: =O5-S5 -> 47377.45 | U5: =IF(N5="USD",(O5/I5/K5),1) -> 1
A6: HMO/2026/00450 | B6: ACUAGRO | C6: 46199 | D6: Pago inmediato | E6: 46199 | F6: ILSE GARCÍA | G6: [LD008-3] ACIDO ACETICO GLACIAL ALIMENTICIO (PORRON NATURAL 50 KG INC) | H6: KG | I6: 200 | J6: 32.5 | K6: 43 | L6: 2100 | M6: 0.24418605 | N6: MXN | O6: 8600 | P6: =MONTH(C6) -> 6 | Q6: =WEEKNUM(C6) -> 26 | R6: =VLOOKUP(G6,Catalogo!A:B,2,0) -> ACIDO ACETICO GLACIAL ALIMENTICIO | S6: =(K6-J6)*I6*U6 -> 2100 | T6: =O6-S6 -> 6500 | U6: =IF(N6="USD",(O6/I6/K6),1) -> 1
A7: HMO/2026/00449 | B7: ACUAGRO | C7: 46199 | D7: Pago inmediato | E7: 46199 | F7: ILSE GARCÍA | G7: [LD012] ACIDO CITRICO WEIFANG SACO 25 KG | H7: KG | I7: 500 | J7: 22.43328 | K7: 33 | L7: 5283.36 | M7: 0.32020364 | N7: MXN | O7: 16500 | P7: =MONTH(C7) -> 6 | Q7: =WEEKNUM(C7) -> 26 | R7: =VLOOKUP(G7,Catalogo!A:B,2,0) -> ACIDO CITRICO WEIFANG | S7: =(K7-J7)*I7*U7 -> 5283.36 | T7: =O7-S7 -> 11216.64 | U7: =IF(N7="USD",(O7/I7/K7),1) -> 1
A8: HMO/2026/00448 | B8: ACUAGRO | C8: 46199 | D8: Pago inmediato | E8: 46199 | F8: ILSE GARCÍA | G8: [LD016-12] ACIDO FOSFORICO CLARIFICADO 85% (TOTE 1575 KG INC) | H8: KG | I8: 3150 | J8: 29.897692 | K8: 36.69 | L8: 21395.77 | M8: 0.18512696 | N8: MXN | O8: 115573.5 | P8: =MONTH(C8) -> 6 | Q8: =WEEKNUM(C8) -> 26 | R8: =VLOOKUP(G8,Catalogo!A:B,2,0) -> ACIDO FOSFORICO CLARIFICADO 85% | S8: =(K8-J8)*I8*U8 -> 21395.77 | T8: =O8-S8 -> 94177.73 | U8: =IF(N8="USD",(O8/I8/K8),1) -> 1
A9: HMO/2026/00448 | B9: ACUAGRO | C9: 46199 | D9: Pago inmediato | E9: 46199 | F9: ILSE GARCÍA | G9: [LD014-4] ACIDO FOSFORICO 52% VERDE (TOTE 1680 KG A/C) | H9: KG | I9: 5040 | J9: 21.0312 | K9: 23.51 | L9: 12493.152 | M9: 0.10543598 | N9: MXN | O9: 118490.4 | P9: =MONTH(C9) -> 6 | Q9: =WEEKNUM(C9) -> 26 | R9: =VLOOKUP(G9,Catalogo!A:B,2,0) -> ACIDO FOSFORICO 52% VERDE | S9: =(K9-J9)*I9*U9 -> 12493.152 | T9: =O9-S9 -> 105997.25 | U9: =IF(N9="USD",(O9/I9/K9),1) -> 1
A10: CLN/2026/00163 | B10: GRUBOSA COMERCIAL | C10: 46199 | D10: 30 Días | E10: 46229 | F10: MATEO LÓPEZ | G10: [LD073-2] LESS 70% (TAMBOR PLASTICO 170 KG INC) | H10: KG | I10: 170 | J10: 38.361235 | K10: 48 | L10: 1638.5901 | M10: 0.2008076 | N10: MXN | O10: 8160 | P10: =MONTH(C10) -> 6 | Q10: =WEEKNUM(C10) -> 26 | R10: =VLOOKUP(G10,Catalogo!A:B,2,0) -> LESS 70% | S10: =(K10-J10)*I10*U10 -> 1638.59 | T10: =O10-S10 -> 6521.41 | U10: =IF(N10="USD",(O10/I10/K10),1) -> 1
A11: HMO/2026/00447 | B11: SAUL AYON REYNA | C11: 46198 | D11: 30 Días | E11: 46198 | F11: ILSE GARCÍA | G11: [LD052-2] ESTIREN ACRILICA (TAMBOR LAMINA 180 KG INC) | H11: KG | I11: 1800 | J11: 31.879394 | K11: 39 | L11: 12817.091 | M11: 0.18257964 | N11: MXN | O11: 70200 | P11: =MONTH(C11) -> 6 | Q11: =WEEKNUM(C11) -> 26 | R11: =VLOOKUP(G11,Catalogo!A:B,2,0) -> ESTIREN ACRILICA | S11: =(K11-J11)*I11*U11 -> 12817.091 | T11: =O11-S11 -> 57382.909 | U11: =IF(N11="USD",(O11/I11/K11),1) -> 1
A12: HMO/2026/00446 | B12: JESUS ALFREDO AYON REYNA | C12: 46198 | D12: 30 Días | E12: 46228 | F12: ILSE GARCÍA | G12: [LD052-2] ESTIREN ACRILICA (TAMBOR LAMINA 180 KG INC) | H12: KG | I12: 1440 | J12: 31.879389 | K12: 42 | L12: 14573.68 | M12: 0.24096693 | N12: MXN | O12: 60480 | P12: =MONTH(C12) -> 6 | Q12: =WEEKNUM(C12) -> 26 | R12: =VLOOKUP(G12,Catalogo!A:B,2,0) -> ESTIREN ACRILICA | S12: =(K12-J12)*I12*U12 -> 14573.68 | T12: =O12-S12 -> 45906.32 | U12: =IF(N12="USD",(O12/I12/K12),1) -> 1
A13: HMO/2026/00444 | B13: JESUS FRANCISCO OLMOS CASTRO | C13: 46198 | D13: 30 Días | E13: 46228 | F13: FREDY SALAS | G13: [LD065] HIPOCLORITO DE CALCIO GRANULAR HTH SKU 30034 CUÑETE 45 KG | H13: KG | I13: 135 | J13: 61.976444 | K13: 88.1 | L13: 3526.6801 | M13: 0.29652163 | N13: MXN | O13: 11893.5 | P13: =MONTH(C13) -> 6 | Q13: =WEEKNUM(C13) -> 26 | R13: =VLOOKUP(G13,Catalogo!A:B,2,0) -> HIPOCLORITO DE CALCIO GRANULAR HTH | S13: =(K13-J13)*I13*U13 -> 3526.6801 | T13: =O13-S13 -> 8366.8199 | U13: =IF(N13="USD",(O13/I13/K13),1) -> 1
... A53: CLN/2026/00155 | B53: AGRONATURART BIO TECH | C53: 46188 | D53: 30 Días | E53: 46218 | F53: ILSE GARCÍA | G53: [LD012] ACIDO CITRICO WEIFANG SACO 25 KG | H53: KG | I53: 200 | J53: 24.3366 | K53: 36 | L53: 2332.68 | M53: 0.32398333 | N53: MXN | O53: 7200 | P53: =MONTH(C53) -> 6 | Q53: =WEEKNUM(C53) -> 25 | R53: =VLOOKUP(G53,Catalogo!A:B,2,0) -> ACIDO CITRICO WEIFANG | S53: =(K53-J53)*I53*U53 -> 2332.68 | T53: =O53-S53 -> 4867.32 | U53: =IF(N53="USD",(O53/I53/K53),1) -> 1
A54: CLN/2026/00154 | B54: OSWALDO GARCIA MARTINEZ | C54: 46188 | E54: 46188 | F54: MATEO LÓPEZ | G54: [LD065] HIPOCLORITO DE CALCIO GRANULAR HTH SKU 30034 CUÑETE 45 KG | H54: KG | I54: 225 | J54: 61.976444 | K54: 83.5 | L54: 4842.8001 | M54: 0.25776714 | N54: MXN | O54: 18787.5 | P54: =MONTH(C54) -> 6 | Q54: =WEEKNUM(C54) -> 25 | R54: =VLOOKUP(G54,Catalogo!A:B,2,0) -> HIPOCLORITO DE CALCIO GRANULAR HTH | S54: =(K54-J54)*I54*U54 -> 4842.8001 | T54: =O54-S54 -> 13944.7 | U54: =IF(N54="USD",(O54/I54/K54),1) -> 1
A55: HMO/2026/00409 | B55: AQUASTORE SUMINISTROS ACUICOLAS DEL PACIFICO | C55: 46186 | D55: 30 Días | E55: 46216 | F55: MATEO LÓPEZ | G55: [LD065] HIPOCLORITO DE CALCIO GRANULAR HTH SKU 30034 CUÑETE 45 KG | H55: KG | I55: 135 | J55: 3.565286 | K55: 5 | L55: 193.68639 | M55: 0.2869428 | N55: USD | O55: 11733.73 | P55: =MONTH(C55) -> 6 | Q55: =WEEKNUM(C55) -> 24 | R55: =VLOOKUP(G55,Catalogo!A:B,2,0) -> HIPOCLORITO DE CALCIO GRANULAR HTH | S55: =(K55-J55)*I55*U55 -> 3366.9093 | T55: =O55-S55 -> 8366.8207 | U55: =IF(N55="USD",(O55/I55/K55),1) -> 17.383304
A56: HMO/2026/00408 | B56: KESECOME ALIMENTARIA | C56: 46186 | D56: 30 Días | E56: 46216 | F56: FREDY SALAS | G56: [LD008-2] ACIDO ACETICO GLACIAL ALIMENTICIO (PORRON NATURAL 20 KG INC) | H56: KG | I56: 220 | J56: 26.250773 | K56: 43 | L56: 3684.8299 | M56: 0.38951691 | N56: MXN | O56: 9460 | P56: =MONTH(C56) -> 6 | Q56: =WEEKNUM(C56) -> 24 | R56: =VLOOKUP(G56,Catalogo!A:B,2,0) -> ACIDO ACETICO GLACIAL ALIMENTICIO | S56: =(K56-J56)*I56*U56 -> 3684.8299 | T56: =O56-S56 -> 5775.1701 | U56: =IF(N56="USD",(O56/I56/K56),1) -> 1
A57: HMO/2026/00407 | B57: AQUASTORE SUMINISTROS ACUICOLAS DEL PACIFICO | C57: 46186 | D57: 30 Días | E57: 46216 | F57: MATEO LÓPEZ | G57: [LD065] HIPOCLORITO DE CALCIO GRANULAR HTH SKU 30034 CUÑETE 45 KG | H57: KG | I57: 225 | J57: 3.558822 | K57: 5 | L57: 324.26505 | M57: 0.2882356 | N57: USD | O57: 19556.21 | P57: =MONTH(C57) -> 6 | Q57: =WEEKNUM(C57) -> 24 | R57: =VLOOKUP(G57,Catalogo!A:B,2,0) -> HIPOCLORITO DE CALCIO GRANULAR HTH | S57: =(K57-J57)*I57*U57 -> 5636.7959 | T57: =O57-S57 -> 13919.414 | U57: =IF(N57="USD",(O57/I57/K57),1) -> 17.383298
A58: CLN/2026/00153 | B58: INDUSTRIAL AGROBIOLOGICOS DEL NOROESTE | C58: 46186 | D58: 30 Días | E58: 46216 | F58: ILSE GARCÍA | G58: [LD083-6] NONIL FENOL 10 MOLES (TAMBOR PLASTICO 220 KG INC) | H58: KG | I58: 220 | J58: 52.717 | K58: 62 | L58: 2042.26 | M58: 0.14972581 | N58: MXN | O58: 13640 | P58: =MONTH(C58) -> 6 | Q58: =WEEKNUM(C58) -> 24 | R58: =VLOOKUP(G58,Catalogo!A:B,2,0) -> NONIL FENOL 10 MOLES | S58: =(K58-J58)*I58*U58 -> 2042.26 | T58: =O58-S58 -> 11597.74 | U58: =IF(N58="USD",(O58/I58/K58),1) -> 1
A59: HMO/2026/00406 | B59: "PUBLICO EN GENERAL" | C59: 46185 | D59: Pago inmediato | E59: 46185 | F59: ILSE GARCÍA | G59: [LD052-2] ESTIREN ACRILICA (TAMBOR LAMINA 180 KG INC) | H59: KG | I59: 1800 | J59: 31.486083 | K59: 39 | L59: 13525.051 | M59: 0.19266454 | N59: MXN | O59: 70200 | P59: =MONTH(C59) -> 6 | Q59: =WEEKNUM(C59) -> 24 | R59: =VLOOKUP(G59,Catalogo!A:B,2,0) -> ESTIREN ACRILICA | S59: =(K59-J59)*I59*U59 -> 13525.051 | T59: =O59-S59 -> 56674.949 | U59: =IF(N59="USD",(O59/I59/K59),1) -> 1
A60: HMO/2026/00405 | B60: GRUPO OMC DEL NOROESTE | C60: 46185 | D60: 15 Días | E60: 46215 | F60: FREDY SALAS | G60: [LD065] HIPOCLORITO DE CALCIO GRANULAR HTH SKU 30034 CUÑETE 45 KG | H60: KG | I60: 270 | J60: 3.565286 | K60: 4.6 | L60: 279.37278 | M60: 0.22493783 | N60: USD | O60: 21590.06 | P60: =MONTH(C60) -> 6 | Q60: =WEEKNUM(C60) -> 24 | R60: =VLOOKUP(G60,Catalogo!A:B,2,0) -> HIPOCLORITO DE CALCIO GRANULAR HTH | S60: =(K60-J60)*I60*U60 -> 4856.4212 | T60: =O60-S60 -> 16733.639 | U60: =IF(N60="USD",(O60/I60/K60),1) -> 17.383301
A61: HMO/2026/00404 | B61: JESUS ALFREDO AYON REYNA | C61: 46185 | D61: 30 Días | E61: 46215 | F61: ILSE GARCÍA | G61: [LD022] ALCOHOL POLIVINILICO PVOH 08850 SACO 20 KG | H61: KG | I61: 1000 | J61: 47.10633 | K61: 58 | L61: 10893.67 | M61: 0.1878219 | N61: MXN | O61: 58000 | P61: =MONTH(C61) -> 6 | Q61: =WEEKNUM(C61) -> 24 | R61: =VLOOKUP(G61,Catalogo!A:B,2,0) -> ALCOHOL POLIVINILICO PVOH 08850 | S61: =(K61-J61)*I61*U61 -> 10893.67 | T61: =O61-S61 -> 47106.33 | U61: =IF(N61="USD",(O61/I61/K61),1) -> 1
A62: HMO/2026/00403 | B62: JESUS ALFREDO AYON REYNA | C62: 46185 | D62: 30 Días | E62: 46215 | F62: ILSE GARCÍA | G62: [LD022] ALCOHOL POLIVINILICO PVOH 08850 SACO 20 KG | H62: KG | I62: 1000 | J62: 47.10633 | K62: 58 | L62: 10893.67 | M62: 0.1878219 | N62: MXN | O62: 58000 | P62: =MONTH(C62) -> 6 | Q62: =WEEKNUM(C62) -> 24 | R62: =VLOOKUP(G62,Catalogo!A:B,2,0) -> ALCOHOL POLIVINILICO PVOH 08850 | S62: =(K62-J62)*I62*U62 -> 10893.67 | T62: =O62-S62 -> 47106.33 | U62: =IF(N62="USD",(O62/I62/K62),1) -> 1
A63: HMO/2026/00402 | B63: JESUS ALFREDO AYON REYNA | C63: 46185 | D63: 30 Días | E63: 46215 | F63: ILSE GARCÍA | G63: [LD022] ALCOHOL POLIVINILICO PVOH 08850 SACO 20 KG | H63: KG | I63: 1000 | J63: 47.10633 | K63: 58 | L63: 10893.67 | M63: 0.1878219 | N63: MXN | O63: 58000 | P63: =MONTH(C63) -> 6 | Q63: =WEEKNUM(C63) -> 24 | R63: =VLOOKUP(G63,Catalogo!A:B,2,0) -> ALCOHOL POLIVINILICO PVOH 08850 | S63: =(K63-J63)*I63*U63 -> 10893.67 | T63: =O63-S63 -> 47106.33 | U63: =IF(N63="USD",(O63/I63/K63),1) -> 1
A64: HMO/2026/00401 | B64: JOCLA PRODUCTOS DE LIMPIEZA | C64: 46185 | D64: Pago inmediato | E64: 46185 | F64: MATEO LÓPEZ | G64: [LD073-2] LESS 70% (TAMBOR PLASTICO 170 KG INC) | H64: KG | I64: 340 | J64: 38.099412 | K64: 46.5 | L64: 2856.1999 | M64: 0.18065781 | N64: MXN | O64: 15810 | P64: =MONTH(C64) -> 6 | Q64: =WEEKNUM(C64) -> 24 | R64: =VLOOKUP(G64,Catalogo!A:B,2,0) -> LESS 70% | S64: =(K64-J64)*I64*U64 -> 2856.1999 | T64: =O64-S64 -> 12953.8 | U64: =IF(N64="USD",(O64/I64/K64),1) -> 1
A65: HMO/2026/00400 | B65: "PUBLICO EN GENERAL" | C65: 46185 | D65: Pago inmediato | E65: 46185 | F65: ILSE GARCÍA | G65: [LD052-2] ESTIREN ACRILICA (TAMBOR LAMINA 180 KG INC) | H65: KG | I65: 2160 | J65: 31.486083 | K65: 39 | L65: 16230.061 | M65: 0.19266454 | N65: MXN | O65: 84240 | P65: =MONTH(C65) -> 6 | Q65: =WEEKNUM(C65) -> 24 | R65: =VLOOKUP(G65,Catalogo!A:B,2,0) -> ESTIREN ACRILICA | S65: =(K65-J65)*I65*U65 -> 16230.061 | T65: =O65-S65 -> 68009.939 | U65: =IF(N65="USD",(O65/I65/K65),1) -> 1
A66: HMO/2026/00399 | B66: ADQUISICIONES PADRE KINO | C66: 46185 | D66: Pago inmediato | E66: 46185 | F66: ILSE GARCÍA | G66: [LD094] POTASA CAUSTICA EN ESCAMA CHINA SACO 25 KG | H66: KG | I66: 2000 | J66: 2.315533 | K66: 2.85 | L66: 1068.934 | M66: 0.18753228 | N66: USD | O66: 99084.81 | P66: =MONTH(C66) -> 6 | Q66: =WEEKNUM(C66) -> 24 | R66: =VLOOKUP(G66,Catalogo!A:B,2,0) -> POTASA CAUSTICA EN ESCAMA CHINA | S66: =(K66-J66)*I66*U66 -> 18581.6 | T66: =O66-S66 -> 80503.21 | U66: =IF(N66="USD",(O66/I66/K66),1) -> 17.3833
... A146: HMO/2026/00336 | B146: JUAN HERMENEGILDO OLIVAS MENDOZA | C146: 46160 | D146: Pago inmediato | E146: 46160 | F146: ILSE GARCÍA | G146: [LD052-2] ESTIREN ACRILICA (TAMBOR LAMINA 180 KG INC) | H146: KG | I146: 360 | J146: 33.561472 | K146: 45 | L146: 4117.8701 | M146: 0.25418951 | N146: MXN | O146: 16200 | P146: =MONTH(C146) -> 5 | Q146: =WEEKNUM(C146) -> 21 | R146: =VLOOKUP(G146,Catalogo!A:B,2,0) -> ESTIREN ACRILICA | S146: =(K146-J146)*I146*U146 -> 4117.8701 | T146: =O146-S146 -> 12082.13 | U146: =IF(N146="USD",(O146/I146/K146),1) -> 1
A147: CLN/2026/00129 | B147: ANTONIO ROMAN PEÑA | C147: 46160 | D147: 30 Días | E147: 46190 | F147: ILSE GARCÍA | G147: [LD065] HIPOCLORITO DE CALCIO GRANULAR HTH SKU 30034 CUÑETE 45 KG | H147: KG | I147: 810 | J147: 3.568835 | K147: 4.92 | L147: 18986.079 | M147: 0.27 | N147: USD | O147: 69134.05 | P147: =MONTH(C147) -> 5 | Q147: =WEEKNUM(C147) -> 21 | R147: =VLOOKUP(G147,Catalogo!A:B,2,0) -> HIPOCLORITO DE CALCIO GRANULAR HTH | S147: 13650.84 | T147: =O147-S147 -> 55483.21 | U147: =IF(N147="USD",(O147/I147/K147),1) -> 17.347699
A148: CLN/2026/00128 | B148: JESUS FRANCISCO OLMOS CASTRO | C148: 46160 | D148: 30 Días | E148: 46190 | F148: FREDY SALAS | G148: [LD065] HIPOCLORITO DE CALCIO GRANULAR HTH SKU 30034 CUÑETE 45 KG | H148: KG | I148: 180 | J148: 68.497778 | K148: 87 | L148: 3330.4 | M148: 0.21266922 | N148: MXN | O148: 15660 | P148: =MONTH(C148) -> 5 | Q148: =WEEKNUM(C148) -> 21 | R148: =VLOOKUP(G148,Catalogo!A:B,2,0) -> HIPOCLORITO DE CALCIO GRANULAR HTH | S148: =(K148-J148)*I148*U148 -> 3330.4 | T148: =O148-S148 -> 12329.6 | U148: =IF(N148="USD",(O148/I148/K148),1) -> 1
A149: HMO/2026/00335 | B149: SAUL AYON REYNA | C149: 46158 | D149: 30 Días | E149: 46188 | F149: ILSE GARCÍA | G149: [LD022] ALCOHOL POLIVINILICO PVOH 08850 SACO 20 KG | H149: KG | I149: 500 | J149: 47.80788 | K149: 58 | L149: 5096.06 | M149: 0.17572621 | N149: MXN | O149: 29000 | P149: =MONTH(C149) -> 5 | Q149: =WEEKNUM(C149) -> 20 | R149: =VLOOKUP(G149,Catalogo!A:B,2,0) -> ALCOHOL POLIVINILICO PVOH 08850 | S149: =(K149-J149)*I149*U149 -> 5096.06 | T149: =O149-S149 -> 23903.94 | U149: =IF(N149="USD",(O149/I149/K149),1) -> 1
A150: CLN/2026/00127 | B150: SERVICIOS Y SOLUCIONES ACUICOLAS | C150: 46158 | D150: 30 Días | E150: 46188 | F150: FREDY SALAS | G150: [LD113] TIOSULFATO DE SODIO SACO 25 KG | H150: KG | I150: 100 | J150: 29.7278 | K150: 39 | L150: 927.22 | M150: 0.23774872 | N150: MXN | O150: 3900 | P150: =MONTH(C150) -> 5 | Q150: =WEEKNUM(C150) -> 20 | R150: =VLOOKUP(G150,Catalogo!A:B,2,0) -> TIOSULFATO DE SODIO | S150: =(K150-J150)*I150*U150 -> 927.22 | T150: =O150-S150 -> 2972.78 | U150: =IF(N150="USD",(O150/I150/K150),1) -> 1
A151: HMO/2026/00334 | B151: SAUL AYON REYNA | C151: 46157 | D151: 30 Días | E151: 46187 | F151: ILSE GARCÍA | G151: [LD052-2] ESTIREN ACRILICA (TAMBOR LAMINA 180 KG INC) | H151: KG | I151: 1800 | J151: 33.066172 | K151: 41 | L151: 14280.89 | M151: 0.193508 | N151: MXN | O151: 73800 | P151: =MONTH(C151) -> 5 | Q151: =WEEKNUM(C151) -> 20 | R151: =VLOOKUP(G151,Catalogo!A:B,2,0) -> ESTIREN ACRILICA | S151: =(K151-J151)*I151*U151 -> 14280.89 | T151: =O151-S151 -> 59519.11 | U151: =IF(N151="USD",(O151/I151/K151),1) -> 1
A152: HMO/2026/00332 | B152: AGROBIOLIFE | C152: 46157 | D152: 30 Días | E152: 46187 | F152: ILSE GARCÍA | G152: [LD048] DESPUMAROL PORRON 50 KG INC | H152: KG | I152: 200 | J152: 60.2313 | K152: 68 | L152: 1553.74 | M152: 0.11424559 | N152: MXN | O152: 13600 | P152: =MONTH(C152) -> 5 | Q152: =WEEKNUM(C152) -> 20 | R152: =VLOOKUP(G152,Catalogo!A:B,2,0) -> DESPUMAROL | S152: =(K152-J152)*I152*U152 -> 1553.74 | T152: =O152-S152 -> 12046.26 | U152: =IF(N152="USD",(O152/I152/K152),1) -> 1
A153: HMO/2026/00331 | B153: AGROBIOLIFE | C153: 46157 | D153: 30 Días | E153: 46187 | F153: ILSE GARCÍA | G153: [LD097-2] PROTEINA VEGETAL PVH 11307 (SACO 25 KG) | H153: KG | I153: 1000 | J153: 65.99198 | K153: 78 | L153: 12008.02 | M153: 0.15394897 | N153: MXN | O153: 78000 | P153: =MONTH(C153) -> 5 | Q153: =WEEKNUM(C153) -> 20 | R153: =VLOOKUP(G153,Catalogo!A:B,2,0) -> PROTEINA VEGETAL PVH 11307 | S153: =(K153-J153)*I153*U153 -> 12008.02 | T153: =O153-S153 -> 65991.98 | U153: =IF(N153="USD",(O153/I153/K153),1) -> 1
A154: HMO/2026/00329 | B154: ABEL LOPEZ ROJO | C154: 46157 | D154: Pago inmediato | E154: 46157 | F154: ILSE GARCÍA | G154: [LD096] POTASA CAUSTICA EN ESCAMAS COREANA SACO 25 KG | H154: KG | I154: 75 | J154: 33.992 | K154: 48.3 | L154: 1073.1 | M154: 0.29623188 | N154: MXN | O154: 3622.5 | P154: =MONTH(C154) -> 5 | Q154: =WEEKNUM(C154) -> 20 | R154: =VLOOKUP(G154,Catalogo!A:B,2,0) -> POTASA CAUSTICA EN ESCAMAS COREANA | S154: =(K154-J154)*I154*U154 -> 1073.1 | T154: =O154-S154 -> 2549.4 | U154: =IF(N154="USD",(O154/I154/K154),1) -> 1
A155: HMO/2026/00328 | B155: KESECOME ALIMENTARIA | C155: 46157 | D155: 30 Días | E155: 46187 | F155: FREDY SALAS | G155: [LD072-2] LESS 28% (TAMBOR PLASTICO 220 KG INC) | H155: KG | I155: 220 | J155: 20.902227 | K155: 35 | L155: 3101.5101 | M155: 0.40279351 | N155: MXN | O155: 7700 | P155: =MONTH(C155) -> 5 | Q155: =WEEKNUM(C155) -> 20 | R155: =VLOOKUP(G155,Catalogo!A:B,2,0) -> LESS 28% | S155: =(K155-J155)*I155*U155 -> 3101.5101 | T155: =O155-S155 -> 4598.4899 | U155: =IF(N155="USD",(O155/I155/K155),1) -> 1
A156: HMO/2026/00327 | B156: DISTRIBUIDORA EQUINA SMC | C156: 46156 | D156: 30 Días | E156: 46186 | F156: ILSE GARCÍA | G156: [LD137-2] ACEITE MINERAL LTS (TAMBOR PLASTICO 200 L INC) | H156: L | I156: 200 | J156: 48 | K156: 58 | L156: 2000 | M156: 0.17241379 | N156: MXN | O156: 11600 | P156: =MONTH(C156) -> 5 | Q156: =WEEKNUM(C156) -> 20 | R156: =VLOOKUP(G156,Catalogo!A:B,2,0) -> ACEITE MINERAL | S156: =(K156-J156)*I156*U156 -> 2000 | T156: =O156-S156 -> 9600 | U156: =IF(N156="USD",(O156/I156/K156),1) -> 1
A157: CLN/2026/00126 | B157: MARIA DEL CARMEN RIVERA QUINTERO | C157: 46156 | D157: 30 Días | E157: 46186 | F157: FREDY SALAS | G157: [LD116] TRICLORO POLVO CUÑETE 50 KG | H157: KG | I157: 250 | J157: 45.3652 | K157: 54 | L157: 2158.7 | M157: 0.1599037 | N157: MXN | O157: 13500 | P157: =MONTH(C157) -> 5 | Q157: =WEEKNUM(C157) -> 20 | R157: =VLOOKUP(G157,Catalogo!A:B,2,0) -> TRICLORO POLVO | S157: =(K157-J157)*I157*U157 -> 2158.7 | T157: =O157-S157 -> 11341.3 | U157: =IF(N157="USD",(O157/I157/K157),1) -> 1
A158: HMO/2026/00326 | B158: ABASTECEDORA HIGIENICA DE SONORA | C158: 46155 | D158: 30 Días | E158: 46185 | F158: ILSE GARCÍA | G158: [LD016-1] ACIDO FOSFORICO CLARIFICADO 85% (PORRON NATURAL 30 KG INC) | H158: KG | I158: 270 | J158: 1.840587 | K158: 2.75 | L158: 245.54151 | M158: 0.33069564 | N158: USD | O158: 12809.61 | P158: =MONTH(C158) -> 5 | Q158: =WEEKNUM(C158) -> 20 | R158: =VLOOKUP(G158,Catalogo!A:B,2,0) -> ACIDO FOSFORICO CLARIFICADO 85% | S158: =(K158-J158)*I158*U158 -> 4236.0821 | T158: =O158-S158 -> 8573.5279 | U158: =IF(N158="USD",(O158/I158/K158),1) -> 17.252
...

Sheet Ventas
D1: Fecha corte | E1: 46199 | J1: Vendedor | K1: (Todas)
D2: Semana | E2: =WEEKNUM(E1) -> 26
A3: Vendedor / Cliente / Producto | B3: Cantidad | C3: Ut. Unit. | D3: Venta MN | E3: Ut Bruta MN. | F3: Margen% | G3: =GETPIVOTDATA("Ut Bruta MN.",$A$3)/GETPIVOTDATA("Venta MN",$A$3) -> 0.20952055 | J3: Producto / Cliente | K3: Cantidad | L3: Ut. Unit. | M3: Venta MN | N3: Ut Bruta MN | O3: Margen % | Q3: Cliente / Producto | R3: Cantidad | S3: Ut. Unit. | T3: Venta MN | U3: Ut Bruta MN | W3: Vendedor / Producto | X3: Cantidad | Y3: Ut. Unit. | Z3: Venta MN | AA3: Ut Bruta MN. | AB3: Margen% | AC3: =GETPIVOTDATA("Ut Bruta MN.",$A$3)/GETPIVOTDATA("Venta MN",$A$3) -> 0.20952055
A4: ILSE GARCÍA | B4: 63255 | C4: 10.036367 | D4: 3070157.4 | E4: 634850.37 | F4: 0.20678105 | J4: HIPOCLORITO DE CALCIO GRANULAR HTH | K4: 21015 | L4: 17.782982 | M4: 1651308.4 | N4: 373709.37 | O4: 0.22631107 | Q4: ADQUISICIONES PADRE KINO | R4: 12350 | S4: 7.4655939 | T4: 520526.67 | U4: 92200.085 | W4: ILSE GARCÍA | X4: 63255 | Y4: 10.036367 | Z4: 3070157.4 | AA4: 634850.37 | AB4: 0.20678105
A5: FREDY SALAS | B5: 8890 | C5: 14.964042 | D5: 618700.63 | E5: 133030.34 | F5: 0.21501568 | J5: ESTIREN ACRILICA | K5: 10980 | L5: 7.4537111 | M5: 423990 | N5: 81841.748 | O5: 0.19302754 | Q5: ACUAGRO | R5: 12000 | S5: 6.554086 | T5: 361401.2 | U5: 78649.032 | W5: FREDY SALAS | X5: 8890 | Y5: 14.964042 | Z5: 618700.63 | AA5: 133030.34 | AB5: 0.21501568
A6: MATEO LÓPEZ | B6: 8497 | C6: 14.654596 | D6: 570393.98 | E6: 124520.1 | F6: 0.21830542 | J6: TRIETANOLAMINA | K6: 10350 | L6: 7.5925922 | M6: 427256.25 | N6: 78583.329 | O6: 0.18392552 | Q6: JESUS ALFREDO AYON REYNA | R6: 7500 | S6: 8.5601745 | T6: 322630 | U6: 64201.309 | W6: MATEO LÓPEZ | X6: 8497 | Y6: 14.654596 | Z6: 570393.98 | AA6: 124520.1 | AB6: 0.21830542
A7: Total general | B7: 80642 | C7: 11.066204 | D7: 4259252 | E7: 892400.81 | F7: 0.20952055 | J7: POTASA CAUSTICA EN ESCAMA CHINA | K7: 3400 | L7: 12.783293 | M7: 178270.42 | N7: 43463.196 | O7: 0.24380487 | Q7: NRW CHEMIE MEXICANA | R7: 4500 | S7: 12.671851 | T7: 328079.43 | U7: 57023.33 | W7: Total general | X7: 80642 | Y7: 11.066204 | Z7: 4259252 | AA7: 892400.81 | AB7: 0.20952055
J8: LESS 70% | K8: 3230 | L8: 9.2902288 | M8: 149260 | N8: 30007.439 | O8: 0.2010414 | Q8: ORBEX CHEMICAL | R8: 2700 | S8: 19.693946 | T8: 219428.7 | U8: 53173.654
J9: ALCOHOL POLIVINILICO PVOH 08850 | K9: 3000 | L9: 9.7107733 | M9: 147310 | N9: 29132.32 | O9: 0.197762 | Q9: YERALDIN CASTRO CADENA | R9: 2250 | S9: 21.420872 | T9: 176140.45 | U9: 48196.962
J10: SULFATO DE COBRE PEÑOLES | K10: 2800 | L10: 10.314536 | M10: 209450 | N10: 28880.7 | O10: 0.13788828 | Q10: AQUASTORE SUMINISTROS ACUICOLAS DEL PACIFICO | R10: 2425 | S10: 18.505013 | T10: 187414.58 | U10: 44874.656
J11: ACIDO FOSFORICO 52% VERDE | K11: 8400 | L11: 3.28418 | M11: 165001.2 | N11: 27587.112 | O11: 0.1671934 | Q11: BRAULIO ARIAS URIAS | R11: 2070 | S11: 18.03059 | T11: 163809.45 | U11: 37323.32
J12: HEXAMETAFOSFATO DE SODIO POLVO TECNICO | K12: 1000 | L12: 22.61324 | M12: 60000 | N12: 22613.24 | O12: 0.37688733 | Q12: SAUL AYON REYNA | R12: 5220 | S12: 6.8928733 | T12: 198360 | U12: 35980.799
J13: ACIDO ASCORBICO | K13: 850 | L13: 23.418071 | M13: 73350 | N13: 19905.36 | O13: 0.27137505 | Q13: MAXICHEMICAL | R13: 2250 | S13: 15.934662 | T13: 171851.13 | U13: 35852.989
J14: CARBONATO DE POTASIO LIGERO ROT | K14: 2000 | L14: 8.55571 | M14: 110000 | N14: 17111.42 | O14: 0.15555836 | Q14: CESAR AUGUSTO VEGA MADRID | R14: 1440 | S14: 19.959684 | T14: 117984.7 | U14: 28741.945
J15: ACIDO FOSFORICO CLARIFICADO 85% | K15: 1150 | L15: 13.719647 | M15: 49516.83 | N15: 15777.595 | O15: 0.31863095 | Q15: ECOTERRA N.V. | R15: 1000 | S15: 25.77917 | T15: 65000 | U15: 25779.17
J16: EXXSOL D-40 | K16: 800 | L16: 16.083494 | M16: 55983.36 | N16: 12866.796 | O16: 0.2298325 | Q16: ABASTECEDORA HIGIENICA DE SONORA | R16: 3220 | S16: 7.0291894 | T16: 115400 | U16: 22633.99
J17: LESS 28% | K17: 2500 | L17: 4.469068 | M17: 45990 | N17: 11172.67 | O17: 0.24293694 | Q17: QMX4 | R17: 1440 | S17: 13.637488 | T17: 106986.18 | U17: 19637.983
J18: NONIL FENOL 10 MOLES | K18: 880 | L18: 11.955272 | M18: 53680 | N18: 10520.64 | O18: 0.19598807 | Q18: LABORATORIOS AEQ | R18: 1710 | S18: 9.6712238 | T18: 126239.7 | U18: 16537.793
J19: EDTA | K19: 475 | L19: 19.844274 | M19: 32650 | N19: 9426.03 | O19: 0.28869923 | Q19: ABQUIM | R19: 720 | S19: 22.815306 | T19: 59796 | U19: 16427.02
... J41: Total general | K41: 80642 | L41: 11.066204 | M41: 4259252 | N41: 892400.81 | O41: 0.20952055 | Q41: LUCINA YARLIN OCHOA QUIÑONEZ | R41: 340 | S41: 12.011176 | T41: 15980 | U41: 4083.7998
Q42: KESECOME ALIMENTARIA | R42: 220 | S42: 16.749227 | T42: 9460 | U42: 3684.8299
Q43: PAPAS RAYGOZA DE CAJEME | R43: 90 | S43: 35.869444 | T43: 8640 | U43: 3228.25
Q44: JESUS FRANCISCO OLMOS CASTRO | R44: 135 | S44: 23.775071 | T44: 11327.26 | U44: 3209.6346
Q45: AGRO PRODUCTOS BALEY | R45: 400 | S45: 7.7997 | T45: 27200 | U45: 3119.88
Q46: INSECTICIDAS DEL PACIFICO | R46: 300 | S46: 8.7894382 | T46: 9738.23 | U46: 2636.8315
Q47: AGROBIOLIFE | R47: 200 | S47: 12.0775 | T47: 8800 | U47: 2415.5
Q48: JESUS ANTONIO PACHECO NIEBLAS | R48: 220 | S48: 10.230545 | T48: 13200 | U48: 2250.7199
Q49: JIMMY JAVIER VITE QUIMIZ | R49: 100 | S49: 21.1492 | T49: 6400 | U49: 2114.92
Q50: ACUICOLA BOCA | R50: 90 | S50: 23.255889 | T50: 7670.7 | U50: 2093.03
Q51: GENITECH | R51: 42 | S51: 48.257143 | T51: 18270 | U51: 2026.8
Q52: JUAN HERMENEGILDO OLIVAS MENDOZA | R52: 180 | S52: 10.69 | T52: 7470 | U52: 1924.2
Q53: JESUS ALEJANDRO GOMEZ ESPINOZA | R53: 170 | S53: 10.751647 | T53: 8160 | U53: 1827.78
... Q63: Total general | R63: 80642 | S63: 11.066204 | T63: 4259252 | U63: 892400.81

Sheet BD Cobranza
A1: Fecha de factura | B1: Número | C1: Cliente | D1: Importe | E1: IVA | F1: Total | G1: Fecha de vencimiento | H1: Estatus | I1: Estado de pago | J1: Fecha último pago | K1: Semana | L1: Vendedor | M1: Términos de pago | N1: Mes | O1: Semana | Q1: SE BAJA TODO EL MES | S1: ILSE GARCIA | U1: CREDITO
A2: 46199 | B2: HMO/2026/00454 | C2: "PUBLICO EN GENERAL" | D2: 70200 | E2: 11232 | F2: 81432 | G2: 46199 | H2: Vigente | I2: Pagado | J2: 46199 | K2: Semana 4 | L2: ILSE GARCÍA | M2: Contado | N2: =MONTH(J2) -> 6 | O2: =WEEKNUM(J2) -> 26
A3: 46199 | B3: HMO/2026/00453 | C3: "PUBLICO EN GENERAL" | D3: 70200 | E3: 11232 | F3: 81432 | G3: 46199 | H3: Vigente | I3: Pagado | J3: 46199 | K3: Semana 4 | L3: ILSE GARCÍA | M3: Contado | N3: =MONTH(J3) -> 6 | O3: =WEEKNUM(J3) -> 26
A4: 46199 | B4: HMO/2026/00452 | C4: "PUBLICO EN GENERAL" | D4: 35100 | E4: 5616 | F4: 40716 | G4: 46199 | H4: Vigente | I4: Pagado | J4: 46199 | K4: Semana 4 | L4: ILSE GARCÍA | M4: Contado | N4: =MONTH(J4) -> 6 | O4: =WEEKNUM(J4) -> 26
A5: 46199 | B5: HMO/2026/00451 | C5: "PUBLICO EN GENERAL" | D5: 58000 | E5: 9280 | F5: 67280 | G5: 46199 | H5: Vigente | I5: Pagado | J5: 46199 | K5: Semana 4 | L5: ILSE GARCÍA | M5: Contado | N5: =MONTH(J5) -> 6 | O5: =WEEKNUM(J5) -> 26
A6: 46198 | B6: HMO/2026/00447 | C6: SAUL AYON REYNA | D6: 70200 | E6: 11232 | F6: 81432 | G6: 46198 | H6: Vigente | I6: Pagado | J6: 46198 | K6: Semana 4 | L6: ILSE GARCÍA | M6: Contado | N6: =MONTH(J6) -> 6 | O6: =WEEKNUM(J6) -> 26
A7: 46198 | B7: HMO/2026/00445 | C7: ELIA GABRIELA GARCIA MORALES | D7: 59910 | F7: 59910 | G7: 46198 | H7: Vigente | I7: Pagado | J7: 46198 | K7: Semana 4 | L7: ILSE GARCÍA | M7: Contado | N7: =MONTH(J7) -> 6 | O7: =WEEKNUM(J7) -> 26
A8: 46198 | B8: HMO/2026/00444 | C8: JESUS FRANCISCO OLMOS CASTRO | D8: 11893.5 | E8: 1902.96 | F8: 13796.46 | G8: 46228 | H8: Vigente | I8: Pagado | J8: 46198 | K8: Semana 4 | L8: FREDY SALAS | M8: Crédito | N8: =MONTH(J8) -> 6 | O8: =WEEKNUM(J8) -> 26
A9: 46198 | B9: HMO/2026/00441 | C9: ABEL DANIEL MONTENEGRO IZAGUIRRE | D9: 14866.2 | E9: 2378.59 | F9: 17244.79 | G9: 46198 | H9: Vigente | I9: Pagado | J9: 46198 | K9: Semana 4 | L9: ILSE GARCÍA | M9: Contado | N9: =MONTH(J9) -> 6 | O9: =WEEKNUM(J9) -> 26
A10: 46197 | B10: CLN/2026/00161 | C10: "PUBLICO EN GENERAL" | D10: 2500 | E10: 400 | F10: 2900 | G10: 46197 | H10: Vigente | I10: Pagado | J10: 46196 | K10: Semana 4 | L10: MATEO LÓPEZ | M10: Contado | N10: =MONTH(J10) -> 6 | O10: =WEEKNUM(J10) -> 26
A11: 46197 | B11: CLN/2026/00160 | C11: "PUBLICO EN GENERAL" | D11: 2750 | E11: 440 | F11: 3190 | G11: 46197 | H11: Vigente | I11: Pagado | J11: 46195 | K11: Semana 4 | L11: FREDY SALAS | M11: Contado | N11: =MONTH(J11) -> 6 | O11: =WEEKNUM(J11) -> 26
A12: 46196 | B12: CLN/2026/00159 | C12: ACUICOLA MOREMAR | D12: 11407.5 | E12: 1825.2 | F12: 13232.7 | G12: 46196 | H12: Vigente | I12: Pagado | J12: 46196 | K12: Semana 4 | L12: MATEO LÓPEZ | M12: Contado | N12: =MONTH(J12) -> 6 | O12: =WEEKNUM(J12) -> 26
A13: 46196 | B13: CLN/2026/00158 | C13: GRANJA ACUICOLA MAYA | D13: 11407.5 | E13: 1825.2 | F13: 13232.7 | G13: 46196 | H13: Vigente | I13: Pagado | J13: 46196 | K13: Semana 4 | L13: MATEO LÓPEZ | M13: Contado | N13: =MONTH(J13) -> 6 | O13: =WEEKNUM(J13) -> 26
A14: 46195 | B14: HMO/2026/00432 | C14: ZAYDA CAMILA GARCIA GARCIA | D14: 16320 | E14: 2611.2 | F14: 18931.2 | G14: 46195 | H14: Vigente | I14: Pagado | J14: 46195 | K14: Semana 4 | L14: ILSE GARCÍA | M14: Contado | N14: =MONTH(J14) -> 6 | O14: =WEEKNUM(J14) -> 26
A15: 46192 | B15: HMO/2026/00431 | C15: SAUL AYON REYNA | D15: 35100 | E15: 5616 | F15: 40716 | G15: 46222 | H15: Vigente | I15: Pagado | J15: 46192 | K15: Semana 3 | L15: ILSE GARCÍA | M15: Crédito | N15: =MONTH(J15) -> 6 | O15: =WEEKNUM(J15) -> 25
A16: 46192 | B16: HMO/2026/00430 | C16: "PUBLICO EN GENERAL" | D16: 70200 | E16: 11232 | F16: 81432 | G16: 46192 | H16: Vigente | I16: Pagado | J16: 46192 | K16: Semana 3 | L16: ILSE GARCÍA | M16: Contado | N16: =MONTH(J16) -> 6 | O16: =WEEKNUM(J16) -> 25
A17: 46192 | B17: HMO/2026/00429 | C17: "PUBLICO EN GENERAL" | D17: 70200 | E17: 11232 | F17: 81432 | G17: 46192 | H17: Vigente | I17: Pagado | J17: 46192 | K17: Semana 3 | L17: ILSE GARCÍA | M17: Contado | N17: =MONTH(J17) -> 6 | O17: =WEEKNUM(J17) -> 25
A18: 46192 | B18: HMO/2026/00428 | C18: SAUL AYON REYNA | D18: 63180 | E18: 10108.8 | F18: 73288.8 | G18: 46192 | H18: Vigente | I18: Pagado | J18: 46192 | K18: Semana 3 | L18: ILSE GARCÍA | M18: Contado | N18: =MONTH(J18) -> 6 | O18: =WEEKNUM(J18) -> 25
A19: 46190 | B19: HMO/2026/00420 | C19: ABEL DANIEL MONTENEGRO IZAGUIRRE | D19: 7433.1 | E19: 1189.3 | F19: 8622.4 | G19: 46190 | H19: Vigente | I19: Pagado | J19: 46190 | K19: Semana 3 | L19: ILSE GARCÍA | M19: Contado | N19: =MONTH(J19) -> 6 | O19: =WEEKNUM(J19) -> 25
... A74: 46150 | B74: CLN/2026/00122 | C74: RENACER 2001 | D74: 112200 | E74: 17952 | F74: 130152 | G74: 46180 | H74: Vigente | I74: Pagado | J74: 46192 | K74: Semana 3 | L74: ILSE GARCÍA | M74: Crédito | N74: =MONTH(J74) -> 6 | O74: =WEEKNUM(J74) -> 25
A75: 46149 | B75: HMO/2026/00320 | C75: AGROPECUARIA MONTE SINAI | D75: 20000 | F75: 20000 | G75: 46179 | H75: Vigente | I75: Pagado | J75: 46188 | K75: Semana 3 | L75: ILSE GARCÍA | M75: Crédito | N75: =MONTH(J75) -> 6 | O75: =WEEKNUM(J75) -> 25
A76: 46149 | B76: HMO/2026/00319 | C76: AGROPECUARIA MONTE SINAI | D76: 4600 | F76: 4600 | G76: 46179 | H76: Vigente | I76: Pagado | J76: 46188 | K76: Semana 3 | L76: ILSE GARCÍA | M76: Crédito | N76: =MONTH(J76) -> 6 | O76: =WEEKNUM(J76) -> 25
A77: 46149 | B77: CLN/2026/00121 | C77: JESUS ESTEBAN CHAVEZ PRECIADO | D77: 30600 | E77: 4896 | F77: 35496 | G77: 46179 | H77: Vigente | I77: Pagado | J77: 46188 | K77: Semana 3 | L77: MATEO LÓPEZ | M77: Crédito | N77: =MONTH(J77) -> 6 | O77: =WEEKNUM(J77) -> 25
A78: 46148 | B78: HMO/2026/00316 | C78: QMX4 | D78: 38940 | E78: 6230.4 | F78: 45170.4 | G78: 46178 | H78: Vigente | I78: Pagado | J78: 46192 | K78: Semana 3 | L78: FREDY SALAS | M78: Crédito | N78: =MONTH(J78) -> 6 | O78: =WEEKNUM(J78) -> 25
A79: 46147 | B79: HMO/2026/00312 | C79: JESUS ALFREDO AYON REYNA | D79: 68400 | E79: 10944 | F79: 79344 | G79: 46177 | H79: Vigente | I79: Pagado | J79: 46177 | K79: Semana 1 | L79: ILSE GARCÍA | M79: Crédito | N79: =MONTH(J79) -> 6 | O79: =WEEKNUM(J79) -> 23
A80: 46147 | B80: CLN/2026/00119 | C80: SEILSIN/PROVELIM | D80: 17050 | E80: 2728 | F80: 19778 | G80: 46177 | H80: Vigente | I80: Pagado | J80: 46192 | K80: Semana 3 | L80: ILSE GARCÍA | M80: Crédito | N80: =MONTH(J80) -> 6 | O80: =WEEKNUM(J80) -> 25
A81: 46146 | B81: HMO/2026/00305 | C81: AGROPECUARIA MONTE SINAI | D81: 12608.5 | F81: 12608.5 | G81: 46176 | H81: Vigente | I81: Pagado | J81: 46189 | K81: Semana 3 | L81: ILSE GARCÍA | M81: Crédito | N81: =MONTH(J81) -> 6 | O81: =WEEKNUM(J81) -> 25
A82: 46141 | B82: HMO/2026/00300 | C82: EDITH CABRERA GARCIA | D82: 9000 | E82: 1440 | F82: 10440 | G82: 46171 | H82: vencido | I82: Pagado | J82: 46189 | K82: Semana 3 | L82: ILSE GARCÍA | M82: Crédito | N82: =MONTH(J82) -> 6 | O82: =WEEKNUM(J82) -> 25
A83: 46140 | B83: HMO/2026/00291 | C83: LABORATORIOS AEQ | D83: 11264.7 | E83: 1802.35 | F83: 13067.05 | G83: 46170 | H83: vencido | I83: Pagado | J83: 46178 | K83: Semana 1 | L83: ILSE GARCÍA | M83: Crédito | N83: =MONTH(J83) -> 6 | O83: =WEEKNUM(J83) -> 23
A84: 46140 | B84: CLN/2026/00113 | C84: JESUS ESTEBAN CHAVEZ PRECIADO | D84: 30600 | E84: 4896 | F84: 35496 | G84: 46170 | H84: vencido | I84: Pagado | J84: 46181 | K84: Semana 2 | L84: MATEO LÓPEZ | M84: Crédito | N84: =MONTH(J84) -> 6 | O84: =WEEKNUM(J84) -> 24
A85: 46139 | B85: HMO/2026/00283 | C85: JESUS ALEJANDRO GOMEZ ESPINOZA | D85: 8160 | E85: 1305.6 | F85: 9465.6 | G85: 46169 | H85: vencido | I85: Pagado | J85: 46175 | K85: Semana 1 | L85: ILSE GARCÍA | M85: Crédito | N85: =MONTH(J85) -> 6 | O85: =WEEKNUM(J85) -> 23
A86: 46136 | B86: HMO/2026/00278 | C86: PROQUISON | D86: 3749.48 | E86: 599.92 | F86: 4349.4 | G86: 46166 | H86: vencido | I86: Pagado | J86: 46177 | K86: Semana 1 | L86: FREDY SALAS | M86: Crédito | N86: =MONTH(J86) -> 6 | O86: =WEEKNUM(J86) -> 23
A87: 46136 | B87: HMO/2026/00273 | C87: PROQUISON | D87: 3195 | E87: 511.2 | F87: 3706.2 | G87: 46166 | H87: vencido | I87: Pagado | J87: 46177 | K87: Semana 1 | L87: FREDY SALAS | M87: Crédito | N87: =MONTH(J87) -> 6 | O87: =WEEKNUM(J87) -> 23
A88: 46134 | B88: HMO/2026/00265 | C88: PINTURAS DE CAJEME | D88: 12400 | E88: 1984 | F88: 14384 | G88: 46164 | H88: vencido | I88: Pagado | J88: 46177 | K88: Semana 1 | L88: ILSE GARCÍA | M88: Crédito | N88: =MONTH(J88) -> 6 | O88: =WEEKNUM(J88) -> 23
A89: 46132 | B89: HMO/2026/00260 | C89: EULALIO MOLINA TERAN | D89: 27360 | E89: 4377.6 | F89: 31737.6 | G89: 46162 | H89: vencido | I89: Pagado | J89: 46183 | K89: Semana 2 | L89: ILSE GARCÍA | M89: Crédito | N89: =MONTH(J89) -> 6 | O89: =WEEKNUM(J89) -> 24
A90: 46121 | B90: CLN/2026/00093 | C90: AQUASTORE SUMINISTROS ACUICOLAS DEL PACIFICO | D90: 36050.5 | E90: 5768.08 | F90: 41818.58 | G90: 46151 | H90: vencido | I90: Pagado | J90: 46178 | K90: Semana 1 | L90: MATEO LÓPEZ | M90: Crédito | N90: =MONTH(J90) -> 6 | O90: =WEEKNUM(J90) -> 23
A91: 46108 | B91: HMO/2026/00195 | C91: EULALIO MOLINA TERAN | D91: 4750 | E91: 760 | F91: 5510 | G91: 46138 | H91: vencido | I91: Pagado | J91: 46183 | K91: Semana 2 | L91: ILSE GARCÍA | M91: Crédito | N91: =MONTH(J91) -> 6 | O91: =WEEKNUM(J91) -> 24
A92: 46094 | B92: HMO/2026/00167 | C92: EULALIO MOLINA TERAN | D92: 27360 | E92: 4377.6 | F92: 31737.6 | G92: 46124 | H92: vencido | I92: Pagado | J92: 46183 | K92: Semana 2 | L92: ILSE GARCÍA | M92: Crédito | N92: =MONTH(J92) -> 6 | O92: =WEEKNUM(J92) -> 24
A93: 45814 | B93: CLN/2025/00282 | C93: JESUS FRANCISCO OLMOS CASTRO | D93: 19012.5 | E93: 3042 | F93: 22054.5 | G93: 45844 | H93: vencido | I93: Pagado | J93: 46198 | K93: Semana 4 | L93: FREDY SALAS | M93: Crédito | N93: =MONTH(J93) -> 6 | O93: =WEEKNUM(J93) -> 26
... A107: 46162 | B107: HMO/2026/00344 | C107: ALBA CIRA APODACA SOLIS | D107: 8330 | E107: 1332.8 | F107: 9662.8 | G107: 46162 | H107: Vigente | I107: Pagado | J107: 46161 | K107: Semana 3 | L107: ILSE GARCÍA | M107: Contado | N107: =MONTH(J107) -> 5 | O107: =WEEKNUM(J107) -> 21
...

Sheet BD Cartera
A1: Fecha de factura | B1: Número | C1: Clientes | D1: Importe | E1: IVA | F1: Total | G1: Total pendiente | H1: Importe pendiente | I1: Fecha de vencimiento | J1: Estatus | K1: Estado de pago | L1: Vendedor | M1: Términos de pago | N1: Fecha | O1: Mes | P1: Semana | Q1: Dias vencido | R1: Vencido 0-30 días | S1: Vencido 31-60 días | T1: Vencido 61-90 días | U1: Vencido >90 días | V1: Por vencer | W1: Vigente | Y1: ILSE GARCIA | AA1: CRÉDITO
A2: 46199 | B2: CLN/2026/00163 | C2: GRUBOSA COMERCIAL | D2: 8160 | E2: 1305.6 | F2: 9465.6 | G2: 9465.6 | H2: =D2 -> 8160 | I2: 46229 | J2: Vigente | K2: Sin pagar | L2: MATEO LÓPEZ | M2: Crédito | N2: 46199 | O2: =MONTH(N2) -> 6 | P2: =WEEKNUM(N2) -> 26 | Q2: =IF(J2="Vencido",N2-I2+1,0) -> 0 | R2: =IF(Q2>0,IF(Q2<31,H2,0),0) -> 0 | S2: =IF(Q2>30,IF(Q2<61,H2,0),0) -> 0 | T2: =IF(Q2>60,IF(Q2<91,H2,0),0) -> 0 | U2: =IF(Q2>90,H2,0) -> 0 | V2: =IF(J2="Por vencer",H2,0) -> 0 | W2: =IF(J2="Vigente",H2,0) -> 8160
A3: 46198 | B3: HMO/2026/00446 | C3: JESUS ALFREDO AYON REYNA | D3: 60480 | E3: 9676.8 | F3: 70156.8 | G3: 70156.8 | H3: =D3 -> 60480 | I3: 46228 | J3: Vigente | K3: Sin pagar | L3: ILSE GARCÍA | M3: Crédito | N3: 46199 | O3: =MONTH(N3) -> 6 | P3: =WEEKNUM(N3) -> 26 | Q3: =IF(J3="Vencido",N3-I3+1,0) -> 0 | R3: =IF(Q3>0,IF(Q3<31,H3,0),0) -> 0 | S3: =IF(Q3>30,IF(Q3<61,H3,0),0) -> 0 | T3: =IF(Q3>60,IF(Q3<91,H3,0),0) -> 0 | U3: =IF(Q3>90,H3,0) -> 0 | V3: =IF(J3="Por vencer",H3,0) -> 0 | W3: =IF(J3="Vigente",H3,0) -> 60480
A4: 46198 | B4: HMO/2026/00442 | C4: ALTERA PUBLICIDAD | D4: 83689.2 | E4: 13390.27 | F4: 97079.47 | G4: 97079.47 | H4: =D4 -> 83689.2 | I4: 46243 | J4: Vigente | K4: Sin pagar | L4: ILSE GARCÍA | M4: Crédito | N4: 46199 | O4: =MONTH(N4) -> 6 | P4: =WEEKNUM(N4) -> 26 | Q4: =IF(J4="Vencido",N4-I4+1,0) -> 0 | R4: =IF(Q4>0,IF(Q4<31,H4,0),0) -> 0 | S4: =IF(Q4>30,IF(Q4<61,H4,0),0) -> 0 | T4: =IF(Q4>60,IF(Q4<91,H4,0),0) -> 0 | U4: =IF(Q4>90,H4,0) -> 0 | V4: =IF(J4="Por vencer",H4,0) -> 0 | W4: =IF(J4="Vigente",H4,0) -> 83689.2
A5: 46198 | B5: CLN/2026/00162 | C5: AGRO PRODUCTOS BALEY | D5: 13600 | E5: 2176 | F5: 15776 | G5: 15776 | H5: =D5 -> 13600 | I5: 46228 | J5: Vigente | K5: Sin pagar | L5: MATEO LÓPEZ | M5: Crédito | N5: 46199 | O5: =MONTH(N5) -> 6 | P5: =WEEKNUM(N5) -> 26 | Q5: =IF(J5="Vencido",N5-I5+1,0) -> 0 | R5: =IF(Q5>0,IF(Q5<31,H5,0),0) -> 0 | S5: =IF(Q5>30,IF(Q5<61,H5,0),0) -> 0 | T5: =IF(Q5>60,IF(Q5<91,H5,0),0) -> 0 | U5: =IF(Q5>90,H5,0) -> 0 | V5: =IF(J5="Por vencer",H5,0) -> 0 | W5: =IF(J5="Vigente",H5,0) -> 13600
A6: 46196 | B6: HMO/2026/00440 | C6: PROQUISON | D6: 3195 | E6: 511.2 | F6: 3706.2 | G6: 3706.2 | H6: =D6 -> 3195 | I6: 46226 | J6: Vigente | K6: Sin pagar | L6: FREDY SALAS | M6: Crédito | N6: 46199 | O6: =MONTH(N6) -> 6 | P6: =WEEKNUM(N6) -> 26 | Q6: =IF(J6="Vencido",N6-I6+1,0) -> 0 | R6: =IF(Q6>0,IF(Q6<31,H6,0),0) -> 0 | S6: =IF(Q6>30,IF(Q6<61,H6,0),0) -> 0 | T6: =IF(Q6>60,IF(Q6<91,H6,0),0) -> 0 | U6: =IF(Q6>90,H6,0) -> 0 | V6: =IF(J6="Por vencer",H6,0) -> 0 | W6: =IF(J6="Vigente",H6,0) -> 3195
A7: 46196 | B7: HMO/2026/00439 | C7: JESUS ALFREDO AYON REYNA | D7: 58500 | E7: 9360 | F7: 67860 | G7: 67860 | H7: =D7 -> 58500 | I7: 46226 | J7: Vigente | K7: Sin pagar | L7: ILSE GARCÍA | M7: Crédito | N7: 46199 | O7: =MONTH(N7) -> 6 | P7: =WEEKNUM(N7) -> 26 | Q7: =IF(J7="Vencido",N7-I7+1,0) -> 0 | R7: =IF(Q7>0,IF(Q7<31,H7,0),0) -> 0 | S7: =IF(Q7>30,IF(Q7<61,H7,0),0) -> 0 | T7: =IF(Q7>60,IF(Q7<91,H7,0),0) -> 0 | U7: =IF(Q7>90,H7,0) -> 0 | V7: =IF(J7="Por vencer",H7,0) -> 0 | W7: =IF(J7="Vigente",H7,0) -> 58500
A8: 46196 | B8: HMO/2026/00438 | C8: JESUS ALFREDO AYON REYNA | D8: 58000 | E8: 9280 | F8: 67280 | G8: 67280 | H8: =D8 -> 58000 | I8: 46226 | J8: Vigente | K8: Sin pagar | L8: ILSE GARCÍA | M8: Crédito | N8: 46199 | O8: =MONTH(N8) -> 6 | P8: =WEEKNUM(N8) -> 26 | Q8: =IF(J8="Vencido",N8-I8+1,0) -> 0 | R8: =IF(Q8>0,IF(Q8<31,H8,0),0) -> 0 | S8: =IF(Q8>30,IF(Q8<61,H8,0),0) -> 0 | T8: =IF(Q8>60,IF(Q8<91,H8,0),0) -> 0 | U8: =IF(Q8>90,H8,0) -> 0 | V8: =IF(J8="Por vencer",H8,0) -> 0 | W8: =IF(J8="Vigente",H8,0) -> 58000
A9: 46196 | B9: HMO/2026/00437 | C9: JESUS ALFREDO AYON REYNA | D9: 58000 | E9: 9280 | F9: 67280 | G9: 67280 | H9: =D9 -> 58000 | I9: 46226 | J9: Vigente | K9: Sin pagar | L9: ILSE GARCÍA | M9: Crédito | N9: 46199 | O9: =MONTH(N9) -> 6 | P9: =WEEKNUM(N9) -> 26 | Q9: =IF(J9="Vencido",N9-I9+1,0) -> 0 | R9: =IF(Q9>0,IF(Q9<31,H9,0),0) -> 0 | S9: =IF(Q9>30,IF(Q9<61,H9,0),0) -> 0 | T9: =IF(Q9>60,IF(Q9<91,H9,0),0) -> 0 | U9: =IF(Q9>90,H9,0) -> 0 | V9: =IF(J9="Por vencer",H9,0) -> 0 | W9: =IF(J9="Vigente",H9,0) -> 58000
A10: 46196 | B10: HMO/2026/00436 | C10: JESUS ALFREDO AYON REYNA | D10: 58000 | E10: 9280 | F10: 67280 | G10: 67280 | H10: =D10 -> 58000 | I10: 46226 | J10: Vigente | K10: Sin pagar | L10: ILSE GARCÍA | M10: Crédito | N10: 46199 | O10: =MONTH(N10) -> 6 | P10: =WEEKNUM(N10) -> 26 | Q10: =IF(J10="Vencido",N10-I10+1,0) -> 0 | R10: =IF(Q10>0,IF(Q10<31,H10,0),0) -> 0 | S10: =IF(Q10>30,IF(Q10<61,H10,0),0) -> 0 | T10: =IF(Q10>60,IF(Q10<91,H10,0),0) -> 0 | U10: =IF(Q10>90,H10,0) -> 0 | V10: =IF(J10="Por vencer",H10,0) -> 0 | W10: =IF(J10="Vigente",H10,0) -> 58000
A11: 46196 | B11: HMO/2026/00435 | C11: SEILSIN/PROVELIM | D11: 19470 | E11: 3115.2 | F11: 22585.2 | G11: 22585.2 | H11: =D11 -> 19470 | I11: 46226 | J11: Vigente | K11: Sin pagar | L11: ILSE GARCÍA | M11: Crédito | N11: 46199 | O11: =MONTH(N11) -> 6 | P11: =WEEKNUM(N11) -> 26 | Q11: =IF(J11="Vencido",N11-I11+1,0) -> 0 | R11: =IF(Q11>0,IF(Q11<31,H11,0),0) -> 0 | S11: =IF(Q11>30,IF(Q11<61,H11,0),0) -> 0 | T11: =IF(Q11>60,IF(Q11<91,H11,0),0) -> 0 | U11: =IF(Q11>90,H11,0) -> 0 | V11: =IF(J11="Por vencer",H11,0) -> 0 | W11: =IF(J11="Vigente",H11,0) -> 19470
A12: 46195 | B12: HMO/2026/00433 | C12: EDITH CABRERA GARCIA | D12: 6750 | E12: 1080 | F12: 7830 | G12: 7830 | H12: =D12 -> 6750 | I12: 46225 | J12: Vigente | K12: Sin pagar | L12: ILSE GARCÍA | M12: Crédito | N12: 46199 | O12: =MONTH(N12) -> 6 | P12: =WEEKNUM(N12) -> 26 | Q12: =IF(J12="Vencido",N12-I12+1,0) -> 0 | R12: =IF(Q12>0,IF(Q12<31,H12,0),0) -> 0 | S12: =IF(Q12>30,IF(Q12<61,H12,0),0) -> 0 | T12: =IF(Q12>60,IF(Q12<91,H12,0),0) -> 0 | U12: =IF(Q12>90,H12,0) -> 0 | V12: =IF(J12="Por vencer",H12,0) -> 0 | W12: =IF(J12="Vigente",H12,0) -> 6750
A13: 46192 | B13: HMO/2026/00426 | C13: YERALDIN CASTRO CADENA | D13: 15631.92 | E13: 2501.11 | F13: 18133.03 | G13: 18133.03 | H13: =D13 -> 15631.92 | I13: 46222 | J13: Vigente | K13: Sin pagar | L13: ILSE GARCÍA | M13: Crédito | N13: 46199 | O13: =MONTH(N13) -> 6 | P13: =WEEKNUM(N13) -> 26 | Q13: =IF(J13="Vencido",N13-I13+1,0) -> 0 | R13: =IF(Q13>0,IF(Q13<31,H13,0),0) -> 0 | S13: =IF(Q13>30,IF(Q13<61,H13,0),0) -> 0 | T13: =IF(Q13>60,IF(Q13<91,H13,0),0) -> 0 | U13: =IF(Q13>90,H13,0) -> 0 | V13: =IF(J13="Por vencer",H13,0) -> 0 | W13: =IF(J13="Vigente",H13,0) -> 15631.92
... A45: 46174 | B45: HMO/2026/00369 | C45: "PUBLICO EN GENERAL" | D45: 8000 | E45: 1280 | F45: 9280 | G45: 9280 | H45: =D45 -> 8000 | I45: 46174 | J45: Vencido | K45: Sin pagar | L45: ILSE GARCÍA | M45: Contado | N45: 46199 | O45: =MONTH(N45) -> 6 | P45: =WEEKNUM(N45) -> 26 | Q45: =IF(J45="Vencido",N45-I45+1,0) -> 26 | R45: =IF(Q45>0,IF(Q45<31,H45,0),0) -> 8000 | S45: =IF(Q45>30,IF(Q45<61,H45,0),0) -> 0 | T45: =IF(Q45>60,IF(Q45<91,H45,0),0) -> 0 | U45: =IF(Q45>90,H45,0) -> 0 | V45: =IF(J45="Por vencer",H45,0) -> 0 | W45: =IF(J45="Vigente",H45,0) -> 0
A46: 46171 | B46: CLN/2026/00143 | C46: WALBRO LOS MOCHIS | D46: 381068.6 | E46: 60970.98 | F46: 442039.58 | G46: 2511.59 | H46: =G46/1.16 -> 2165.1638 | I46: 46201 | J46: Por vencer | K46: Pagado parcialmente | L46: ILSE GARCÍA | M46: Crédito | N46: 46199 | O46: =MONTH(N46) -> 6 | P46: =WEEKNUM(N46) -> 26 | Q46: =IF(J46="Vencido",N46-I46+1,0) -> 0 | R46: =IF(Q46>0,IF(Q46<31,H46,0),0) -> 0 | S46: =IF(Q46>30,IF(Q46<61,H46,0),0) -> 0 | T46: =IF(Q46>60,IF(Q46<91,H46,0),0) -> 0 | U46: =IF(Q46>90,H46,0) -> 0 | V46: =IF(J46="Por vencer",H46,0) -> 2165.1638 | W46: =IF(J46="Vigente",H46,0) -> 0
A47: 46170 | B47: HMO/2026/00362 | C47: EULALIO MOLINA TERAN | D47: 42750 | E47: 6840 | F47: 49590 | G47: 49590 | H47: =D47 -> 42750 | I47: 46200 | J47: Por vencer | K47: Sin pagar | L47: ILSE GARCÍA | M47: Crédito | N47: 46199 | O47: =MONTH(N47) -> 6 | P47: =WEEKNUM(N47) -> 26 | Q47: =IF(J47="Vencido",N47-I47+1,0) -> 0 | R47: =IF(Q47>0,IF(Q47<31,H47,0),0) -> 0 | S47: =IF(Q47>30,IF(Q47<61,H47,0),0) -> 0 | T47: =IF(Q47>60,IF(Q47<91,H47,0),0) -> 0 | U47: =IF(Q47>90,H47,0) -> 0 | V47: =IF(J47="Por vencer",H47,0) -> 42750 | W47: =IF(J47="Vigente",H47,0) -> 0
A48: 46170 | B48: CLN/2026/00141 | C48: JESUS ESTEBAN CHAVEZ PRECIADO | D48: 46680 | E48: 7468.8 | F48: 54148.8 | G48: 54148.8 | H48: =D48 -> 46680 | I48: 46200 | J48: Por vencer | K48: Sin pagar | L48: MATEO LÓPEZ | M48: Crédito | N48: 46199 | O48: =MONTH(N48) -> 6 | P48: =WEEKNUM(N48) -> 26 | Q48: =IF(J48="Vencido",N48-I48+1,0) -> 0 | R48: =IF(Q48>0,IF(Q48<31,H48,0),0) -> 0 | S48: =IF(Q48>30,IF(Q48<61,H48,0),0) -> 0 | T48: =IF(Q48>60,IF(Q48<91,H48,0),0) -> 0 | U48: =IF(Q48>90,H48,0) -> 0 | V48: =IF(J48="Por vencer",H48,0) -> 46680 | W48: =IF(J48="Vigente",H48,0) -> 0
A49: 46169 | B49: HMO/2026/00360 | C49: AGROPECUARIA MONTE SINAI | D49: 7015.9 | F49: 7015.9 | G49: 7015.9 | H49: =D49 -> 7015.9 | I49: 46199 | J49: Vencido | K49: Sin pagar | L49: ILSE GARCÍA | M49: Crédito | N49: 46199 | O49: =MONTH(N49) -> 6 | P49: =WEEKNUM(N49) -> 26 | Q49: =IF(J49="Vencido",N49-I49+1,0) -> 1 | R49: =IF(Q49>0,IF(Q49<31,H49,0),0) -> 7015.9 | S49: =IF(Q49>30,IF(Q49<61,H49,0),0) -> 0 | T49: =IF(Q49>60,IF(Q49<91,H49,0),0) -> 0 | U49: =IF(Q49>90,H49,0) -> 0 | V49: =IF(J49="Por vencer",H49,0) -> 0 | W49: =IF(J49="Vigente",H49,0) -> 0
A50: 46169 | B50: HMO/2026/00359 | C50: AGROPECUARIA MONTE SINAI | D50: 20000 | F50: 20000 | G50: 20000 | H50: =D50 -> 20000 | I50: 46199 | J50: Vencido | K50: Sin pagar | L50: ILSE GARCÍA | M50: Crédito | N50: 46199 | O50: =MONTH(N50) -> 6 | P50: =WEEKNUM(N50) -> 26 | Q50: =IF(J50="Vencido",N50-I50+1,0) -> 1 | R50: =IF(Q50>0,IF(Q50<31,H50,0),0) -> 20000 | S50: =IF(Q50>30,IF(Q50<61,H50,0),0) -> 0 | T50: =IF(Q50>60,IF(Q50<91,H50,0),0) -> 0 | U50: =IF(Q50>90,H50,0) -> 0 | V50: =IF(J50="Por vencer",H50,0) -> 0 | W50: =IF(J50="Vigente",H50,0) -> 0
A51: 46169 | B51: CLN/2026/00140 | C51: AGRO PRODUCTOS BALEY | D51: 27200 | E51: 4352 | F51: 31552 | G51: 31552 | H51: =D51 -> 27200 | I51: 46199 | J51: Vencido | K51: Sin pagar | L51: MATEO LÓPEZ | M51: Crédito | N51: 46199 | O51: =MONTH(N51) -> 6 | P51: =WEEKNUM(N51) -> 26 | Q51: =IF(J51="Vencido",N51-I51+1,0) -> 1 | R51: =IF(Q51>0,IF(Q51<31,H51,0),0) -> 27200 | S51: =IF(Q51>30,IF(Q51<61,H51,0),0) -> 0 | T51: =IF(Q51>60,IF(Q51<91,H51,0),0) -> 0 | U51: =IF(Q51>90,H51,0) -> 0 | V51: =IF(J51="Por vencer",H51,0) -> 0 | W51: =IF(J51="Vigente",H51,0) -> 0
A52: 46167 | B52: HMO/2026/00348 | C52: EDITH CABRERA GARCIA | D52: 9000 | E52: 1440 | F52: 10440 | G52: 10440 | H52: =D52 -> 9000 | I52: 46197 | J52: Vencido | K52: Sin pagar | L52: ILSE GARCÍA | M52: Crédito | N52: 46199 | O52: =MONTH(N52) -> 6 | P52: =WEEKNUM(N52) -> 26 | Q52: =IF(J52="Vencido",N52-I52+1,0) -> 3 | R52: =IF(Q52>0,IF(Q52<31,H52,0),0) -> 9000 | S52: =IF(Q52>30,IF(Q52<61,H52,0),0) -> 0 | T52: =IF(Q52>60,IF(Q52<91,H52,0),0) -> 0 | U52: =IF(Q52>90,H52,0) -> 0 | V52: =IF(J52="Por vencer",H52,0) -> 0 | W52: =IF(J52="Vigente",H52,0) -> 0
A53: 46164 | B53: HMO/2026/00347 | C53: NRW CHEMIE MEXICANA | D53: 66167.85 | E53: 10586.86 | F53: 76754.71 | G53: 76754.71 | H53: =D53 -> 66167.85 | I53: 46194 | J53: Vencido | K53: Sin pagar | L53: ILSE GARCÍA | M53: Crédito | N53: 46199 | O53: =MONTH(N53) -> 6 | P53: =WEEKNUM(N53) -> 26 | Q53: =IF(J53="Vencido",N53-I53+1,0) -> 6 | R53: =IF(Q53>0,IF(Q53<31,H53,0),0) -> 66167.85 | S53: =IF(Q53>30,IF(Q53<61,H53,0),0) -> 0 | T53: =IF(Q53>60,IF(Q53<91,H53,0),0) -> 0 | U53: =IF(Q53>90,H53,0) -> 0 | V53: =IF(J53="Por vencer",H53,0) -> 0 | W53: =IF(J53="Vigente",H53,0) -> 0
A54: 46164 | B54: CLN/2026/00134 | C54: QMX4 | D54: 46200 | E54: 7392 | F54: 53592 | G54: 52839.16 | H54: =G54/1.16 -> 45551 | I54: 46194 | J54: Vencido | K54: Pagado parcialmente | L54: FREDY SALAS | M54: Crédito | N54: 46199 | O54: =MONTH(N54) -> 6 | P54: =WEEKNUM(N54) -> 26 | Q54: =IF(J54="Vencido",N54-I54+1,0) -> 6 | R54: =IF(Q54>0,IF(Q54<31,H54,0),0) -> 45551 | S54: =IF(Q54>30,IF(Q54<61,H54,0),0) -> 0 | T54: =IF(Q54>60,IF(Q54<91,H54,0),0) -> 0 | U54: =IF(Q54>90,H54,0) -> 0 | V54: =IF(J54="Por vencer",H54,0) -> 0 | W54: =IF(J54="Vigente",H54,0) -> 0
A55: 46163 | B55: HMO/2026/00345 | C55: BIOMA FORMULACIONES | D55: 110611.14 | E55: 17697.78 | F55: 128308.92 | G55: 128308.92 | H55: =D55 -> 110611.14 | I55: 46193 | J55: Vencido | K55: Sin pagar | L55: ILSE GARCÍA | M55: Crédito | N55: 46199 | O55: =MONTH(N55) -> 6 | P55: =WEEKNUM(N55) -> 26 | Q55: =IF(J55="Vencido",N55-I55+1,0) -> 7 | R55: =IF(Q55>0,IF(Q55<31,H55,0),0) -> 110611.14 | S55: =IF(Q55>30,IF(Q55<61,H55,0),0) -> 0 | T55: =IF(Q55>60,IF(Q55<91,H55,0),0) -> 0 | U55: =IF(Q55>90,H55,0) -> 0 | V55: =IF(J55="Por vencer",H55,0) -> 0 | W55: =IF(J55="Vigente",H55,0) -> 0
A56: 46162 | B56: CLN/2026/00131 | C56: AQUA DUX DE MEXICO | D56: 12000 | E56: 1920 | F56: 13920 | G56: 13920 | H56: =D56 -> 12000 | I56: 46192 | J56: Vencido | K56: Sin pagar | L56: FREDY SALAS | M56: Crédito | N56: 46199 | O56: =MONTH(N56) -> 6 | P56: =WEEKNUM(N56) -> 26 | Q56: =IF(J56="Vencido",N56-I56+1,0) -> 8 | R56: =IF(Q56>0,IF(Q56<31,H56,0),0) -> 12000 | S56: =IF(Q56>30,IF(Q56<61,H56,0),0) -> 0 | T56: =IF(Q56>60,IF(Q56<91,H56,0),0) -> 0 | U56: =IF(Q56>90,H56,0) -> 0 | V56: =IF(J56="Por vencer",H56,0) -> 0 | W56: =IF(J56="Vigente",H56,0) -> 0
A57: 46158 | B57: CLN/2026/00127 | C57: SERVICIOS Y SOLUCIONES ACUICOLAS | D57: 3900 | E57: 624 | F57: 4524 | G57: 4524 | H57: =D57 -> 3900 | I57: 46188 | J57: Vencido | K57: Sin pagar | L57: FREDY SALAS | M57: Crédito | N57: 46199 | O57: =MONTH(N57) -> 6 | P57: =WEEKNUM(N57) -> 26 | Q57: =IF(J57="Vencido",N57-I57+1,0) -> 12 | R57: =IF(Q57>0,IF(Q57<31,H57,0),0) -> 3900 | S57: =IF(Q57>30,IF(Q57<61,H57,0),0) -> 0 | T57: =IF(Q57>60,IF(Q57<91,H57,0),0) -> 0 | U57: =IF(Q57>90,H57,0) -> 0 | V57: =IF(J57="Por vencer",H57,0) -> 0 | W57: =IF(J57="Vigente",H57,0) -> 0
A58: 46147 | B58: HMO/2026/00314 | C58: SERVICIOS Y SOLUCIONES ACUICOLAS | D58: 14000 | E58: 2240 | F58: 16240 | G58: 16240 | H58: =D58 -> 14000 | I58: 46177 | J58: Vencido | K58: Sin pagar | L58: FREDY SALAS | M58: Crédito | N58: 46199 | O58: =MONTH(N58) -> 6 | P58: =WEEKNUM(N58) -> 26 | Q58: =IF(J58="Vencido",N58-I58+1,0) -> 23 | R58: =IF(Q58>0,IF(Q58<31,H58,0),0) -> 14000 | S58: =IF(Q58>30,IF(Q58<61,H58,0),0) -> 0 | T58: =IF(Q58>60,IF(Q58<91,H58,0),0) -> 0 | U58: =IF(Q58>90,H58,0) -> 0 | V58: =IF(J58="Por vencer",H58,0) -> 0 | W58: =IF(J58="Vigente",H58,0) -> 0
A59: 46147 | B59: HMO/2026/00313 | C59: SERVICIOS Y SOLUCIONES ACUICOLAS | D59: 14400 | E59: 2304 | F59: 16704 | G59: 16704 | H59: =D59 -> 14400 | I59: 46177 | J59: Vencido | K59: Sin pagar | L59: FREDY SALAS | M59: Crédito | N59: 46199 | O59: =MONTH(N59) -> 6 | P59: =WEEKNUM(N59) -> 26 | Q59: =IF(J59="Vencido",N59-I59+1,0) -> 23 | R59: =IF(Q59>0,IF(Q59<31,H59,0),0) -> 14400 | S59: =IF(Q59>30,IF(Q59<61,H59,0),0) -> 0 | T59: =IF(Q59>60,IF(Q59<91,H59,0),0) -> 0 | U59: =IF(Q59>90,H59,0) -> 0 | V59: =IF(J59="Por vencer",H59,0) -> 0 | W59: =IF(J59="Vigente",H59,0) -> 0
A60: 46146 | B60: HMO/2026/00306 | C60: KESECOME ALIMENTARIA | D60: 9460 | E60: 1513.6 | F60: 10973.6 | G60: 10973.6 | H60: =D60 -> 9460 | I60: 46176 | J60: Vencido | K60: Sin pagar | L60: FREDY SALAS | M60: Crédito | N60: 46199 | O60: =MONTH(N60) -> 6 | P60: =WEEKNUM(N60) -> 26 | Q60: =IF(J60="Vencido",N60-I60+1,0) -> 24 | R60: =IF(Q60>0,IF(Q60<31,H60,0),0) -> 9460 | S60: =IF(Q60>30,IF(Q60<61,H60,0),0) -> 0 | T60: =IF(Q60>60,IF(Q60<91,H60,0),0) -> 0 | U60: =IF(Q60>90,H60,0) -> 0 | V60: =IF(J60="Por vencer",H60,0) -> 0 | W60: =IF(J60="Vigente",H60,0) -> 0
A61: 46140 | B61: HMO/2026/00294 | C61: SERVICIOS Y SOLUCIONES ACUICOLAS | D61: 7200 | E61: 1152 | F61: 8352 | G61: 8352 | H61: =D61 -> 7200 | I61: 46170 | J61: Vencido | K61: Sin pagar | L61: FREDY SALAS | M61: Crédito | N61: 46199 | O61: =MONTH(N61) -> 6 | P61: =WEEKNUM(N61) -> 26 | Q61: =IF(J61="Vencido",N61-I61+1,0) -> 30 | R61: =IF(Q61>0,IF(Q61<31,H61,0),0) -> 7200 | S61: =IF(Q61>30,IF(Q61<61,H61,0),0) -> 0 | T61: =IF(Q61>60,IF(Q61<91,H61,0),0) -> 0 | U61: =IF(Q61>90,H61,0) -> 0 | V61: =IF(J61="Por vencer",H61,0) -> 0 | W61: =IF(J61="Vigente",H61,0) -> 0
A62: 46140 | B62: HMO/2026/00293 | C62: SERVICIOS Y SOLUCIONES ACUICOLAS | D62: 10350 | E62: 1656 | F62: 12006 | G62: 12006 | H62: =D62 -> 10350 | I62: 46170 | J62: Vencido | K62: Sin pagar | L62: FREDY SALAS | M62: Crédito | N62: 46199 | O62: =MONTH(N62) -> 6 | P62: =WEEKNUM(N62) -> 26 | Q62: =IF(J62="Vencido",N62-I62+1,0) -> 30 | R62: =IF(Q62>0,IF(Q62<31,H62,0),0) -> 10350 | S62: =IF(Q62>30,IF(Q62<61,H62,0),0) -> 0 | T62: =IF(Q62>60,IF(Q62<91,H62,0),0) -> 0 | U62: =IF(Q62>90,H62,0) -> 0 | V62: =IF(J62="Por vencer",H62,0) -> 0 | W62: =IF(J62="Vigente",H62,0) -> 0
A63: 46136 | B63: CLN/2026/00110 | C63: AQUASTORE SUMINISTROS ACUICOLAS DEL PACIFICO | D63: 114984.03 | E63: 18397.44 | F63: 133381.47 | G63: 73452.47 | H63: =G63/1.16 -> 63321.095 | I63: 46166 | J63: Vencido | K63: Pagado parcialmente | L63: MATEO LÓPEZ | M63: Crédito | N63: 46199 | O63: =MONTH(N63) -> 6 | P63: =WEEKNUM(N63) -> 26 | Q63: =IF(J63="Vencido",N63-I63+1,0) -> 34 | R63: =IF(Q63>0,IF(Q63<31,H63,0),0) -> 0 | S63: =IF(Q63>30,IF(Q63<61,H63,0),0) -> 63321.095 | T63: =IF(Q63>60,IF(Q63<91,H63,0),0) -> 0 | U63: =IF(Q63>90,H63,0) -> 0 | V63: =IF(J63="Por vencer",H63,0) -> 0 | W63: =IF(J63="Vigente",H63,0) -> 0
A64: 46120 | B64: HMO/2026/00226 | C64: SERVICIOS Y SOLUCIONES ACUICOLAS | D64: 11047.05 | E64: 1767.53 | F64: 12814.58 | G64: 12814.58 | H64: =D64 -> 11047.05 | I64: 46150 | J64: Vencido | K64: Sin pagar | L64: FREDY SALAS | M64: Crédito | N64: 46199 | O64: =MONTH(N64) -> 6 | P64: =WEEKNUM(N64) -> 26 | Q64: =IF(J64="Vencido",N64-I64+1,0) -> 50 | R64: =IF(Q64>0,IF(Q64<31,H64,0),0) -> 0 | S64: =IF(Q64>30,IF(Q64<61,H64,0),0) -> 11047.05 | T64: =IF(Q64>60,IF(Q64<91,H64,0),0) -> 0 | U64: =IF(Q64>90,H64,0) -> 0 | V64: =IF(J64="Por vencer",H64,0) -> 0 | W64: =IF(J64="Vigente",H64,0) -> 0
A65: 46083 | B65: CLN/2026/00057 | C65: SERVICIOS Y SOLUCIONES ACUICOLAS | D65: 14257.8 | E65: 2281.25 | F65: 16539.05 | G65: 16539.05 | H65: =D65 -> 14257.8 | I65: 46113 | J65: Vencido | K65: Sin pagar | L65: FREDY SALAS | M65: Crédito | N65: 46199 | O65: =MONTH(N65) -> 6 | P65: =WEEKNUM(N65) -> 26 | Q65: =IF(J65="Vencido",N65-I65+1,0) -> 87 | R65: =IF(Q65>0,IF(Q65<31,H65,0),0) -> 0 | S65: =IF(Q65>30,IF(Q65<61,H65,0),0) -> 0 | T65: =IF(Q65>60,IF(Q65<91,H65,0),0) -> 14257.8 | U65: =IF(Q65>90,H65,0) -> 0 | V65: =IF(J65="Por vencer",H65,0) -> 0 | W65: =IF(J65="Vigente",H65,0) -> 0
A66: 46077 | B66: CLN/2026/00052 | C66: DALILA GUADALUPE VALDEZ RENDON | D66: 12825 | E66: 2052 | F66: 14877 | G66: 14877 | H66: =D66 -> 12825 | I66: 46107 | J66: Vencido | K66: Sin pagar | L66: FREDY SALAS | M66: Crédito | N66: 46199 | O66: =MONTH(N66) -> 6 | P66: =WEEKNUM(N66) -> 26 | Q66: =IF(J66="Vencido",N66-I66+1,0) -> 93 | R66: =IF(Q66>0,IF(Q66<31,H66,0),0) -> 0 | S66: =IF(Q66>30,IF(Q66<61,H66,0),0) -> 0 | T66: =IF(Q66>60,IF(Q66<91,H66,0),0) -> 0 | U66: =IF(Q66>90,H66,0) -> 12825 | V66: =IF(J66="Por vencer",H66,0) -> 0 | W66: =IF(J66="Vigente",H66,0) -> 0
